Workbook

Sheet Dashboard
A1: CDaX STUDENT ENROLLMENT & PERFORMANCE DASHBOARD
A2: Dashboard mode | B2: SIMULATED SAMPLE DATA | D2: Course filter | E2: All | G2: Month filter | H2: All
A4: Total Registered Students | D4: Course Enrollments | G4: Active Students | J4: Inactive Students
A5: =IF($H$2="All",COUNTA(Student_Data!$A$4:$A$1000),COUNTIF(Student_Data!$F$4:$F$1000,$H$2)) -> 60 | D5: =COUNTIFS(Enrollment_Data!$C$4:$C$2000,IF($E$2="All","<>",INDEX(Course_Master!$A$4:$A$10,MATCH($E$2,Course_Master!$B$4:$B$10,0))),Enrollment_Data!$F$4:$F$2000,IF($H$2="All","*",$H$2)) -> 104 | G5: =COUNTIFS(Student_Data!$C$4:$C$1000,"Active",Student_Data!$F$4:$F$1000,IF($H$2="All","*",$H$2)) -> 56 | J5: =COUNTIFS(Student_Data!$C$4:$C$1000,"Inactive",Student_Data!$F$4:$F$1000,IF($H$2="All","*",$H$2)) -> 4
A7: Course Completion Rate | D7: Average Assessment Score | G7: Ongoing Enrollments | J7: No Recent Activity
A8: =IFERROR(COUNTIFS(Enrollment_Data!$G$4:$G$2000,"Completed",Enrollment_Data!$C$4:$C$2000,IF($E$2="All","<>",INDEX(Course_Master!$A$4:$A$10,MATCH($E$2,Course_Master!$B$4:$B$10,0))),Enrollment_Data!$F$4:$F$2000,IF($H$2="All","*",$H$2))/COUNTIFS(Enrollment_Data!$C$4:$C$2000,IF($E$2="All","<>",INDEX(Course_Master!$A$4:$A$10,MATCH($E$2,Course_Master!$B$4:$B$10,0))),Enrollment_Data!$F$4:$F$2000,IF($H$2="All","*",$H$2)),0) -> 0.086538462 | D8: =IFERROR(AVERAGEIFS(Enrollment_Data!$I$4:$I$2000,Enrollment_Data!$C$4:$C$2000,IF($E$2="All","<>",INDEX(Course_Master!$A$4:$A$10,MATCH($E$2,Course_Master!$B$4:$B$10,0))),Enrollment_Data!$F$4:$F$2000,IF($H$2="All","*",$H$2)),0) -> 70.554795 | G8: =COUNTIFS(Enrollment_Data!$G$4:$G$2000,"Ongoing",Enrollment_Data!$C$4:$C$2000,IF($E$2="All","<>",INDEX(Course_Master!$A$4:$A$10,MATCH($E$2,Course_Master!$B$4:$B$10,0))),Enrollment_Data!$F$4:$F$2000,IF($H$2="All","*",$H$2)) -> 78 | J8: =COUNTIF(Student_Data!$E$4:$E$1000,"No Recent Activity") -> 45
A11: Course | B11: Enrollments | C11: Completed | D11: Ongoing | E11: Discontinued | F11: Completion Rate | G11: Avg Score | H11: Flag
A12: Complete Java Programming | B12: =COUNTIFS(Enrollment_Data!$D$4:$D$2000,$A12,Enrollment_Data!$F$4:$F$2000,IF($H$2="All","*",$H$2)) -> 12 | C12: =COUNTIFS(Enrollment_Data!$D$4:$D$2000,$A12,Enrollment_Data!$G$4:$G$2000,"Completed",Enrollment_Data!$F$4:$F$2000,IF($H$2="All","*",$H$2)) -> 2 | D12: =COUNTIFS(Enrollment_Data!$D$4:$D$2000,$A12,Enrollment_Data!$G$4:$G$2000,"Ongoing",Enrollment_Data!$F$4:$F$2000,IF($H$2="All","*",$H$2)) -> 6 | E12: =COUNTIFS(Enrollment_Data!$D$4:$D$2000,$A12,Enrollment_Data!$G$4:$G$2000,"Discontinued",Enrollment_Data!$F$4:$F$2000,IF($H$2="All","*",$H$2)) -> 4 | F12: =IFERROR(C12/B12,0) -> 0.16666667 | G12: =IFERROR(AVERAGEIFS(Enrollment_Data!$I$4:$I$2000,Enrollment_Data!$D$4:$D$2000,$A12,Enrollment_Data!$F$4:$F$2000,IF($H$2="All","*",$H$2)),0) -> 66.072727 | H12: =IF(AND(B12>=MEDIAN($B$12:$B$18),F12<0.4),"High enrollment / low completion",IF(G12<50,"Performance review","Monitor")) -> Monitor
A13: Python Programming Mastery | B13: =COUNTIFS(Enrollment_Data!$D$4:$D$2000,$A13,Enrollment_Data!$F$4:$F$2000,IF($H$2="All","*",$H$2)) -> 20 | C13: =COUNTIFS(Enrollment_Data!$D$4:$D$2000,$A13,Enrollment_Data!$G$4:$G$2000,"Completed",Enrollment_Data!$F$4:$F$2000,IF($H$2="All","*",$H$2)) -> 1 | D13: =COUNTIFS(Enrollment_Data!$D$4:$D$2000,$A13,Enrollment_Data!$G$4:$G$2000,"Ongoing",Enrollment_Data!$F$4:$F$2000,IF($H$2="All","*",$H$2)) -> 13 | E13: =COUNTIFS(Enrollment_Data!$D$4:$D$2000,$A13,Enrollment_Data!$G$4:$G$2000,"Discontinued",Enrollment_Data!$F$4:$F$2000,IF($H$2="All","*",$H$2)) -> 6 | F13: =IFERROR(C13/B13,0) -> 0.05 | G13: =IFERROR(AVERAGEIFS(Enrollment_Data!$I$4:$I$2000,Enrollment_Data!$D$4:$D$2000,$A13,Enrollment_Data!$F$4:$F$2000,IF($H$2="All","*",$H$2)),0) -> 71.069231 | H13: =IF(AND(B13>=MEDIAN($B$12:$B$18),F13<0.4),"High enrollment / low completion",IF(G13<50,"Performance review","Monitor")) -> High enrollment / low completion
A14: Flutter Mobile Development | B14: =COUNTIFS(Enrollment_Data!$D$4:$D$2000,$A14,Enrollment_Data!$F$4:$F$2000,IF($H$2="All","*",$H$2)) -> 18 | C14: =COUNTIFS(Enrollment_Data!$D$4:$D$2000,$A14,Enrollment_Data!$G$4:$G$2000,"Completed",Enrollment_Data!$F$4:$F$2000,IF($H$2="All","*",$H$2)) -> 1 | D14: =COUNTIFS(Enrollment_Data!$D$4:$D$2000,$A14,Enrollment_Data!$G$4:$G$2000,"Ongoing",Enrollment_Data!$F$4:$F$2000,IF($H$2="All","*",$H$2)) -> 16 | E14: =COUNTIFS(Enrollment_Data!$D$4:$D$2000,$A14,Enrollment_Data!$G$4:$G$2000,"Discontinued",Enrollment_Data!$F$4:$F$2000,IF($H$2="All","*",$H$2)) -> 1 | F14: =IFERROR(C14/B14,0) -> 0.055555556 | G14: =IFERROR(AVERAGEIFS(Enrollment_Data!$I$4:$I$2000,Enrollment_Data!$D$4:$D$2000,$A14,Enrollment_Data!$F$4:$F$2000,IF($H$2="All","*",$H$2)),0) -> 73 | H14: =IF(AND(B14>=MEDIAN($B$12:$B$18),F14<0.4),"High enrollment / low completion",IF(G14<50,"Performance review","Monitor")) -> High enrollment / low completion
A15: C/C++ Programming Course | B15: =COUNTIFS(Enrollment_Data!$D$4:$D$2000,$A15,Enrollment_Data!$F$4:$F$2000,IF($H$2="All","*",$H$2)) -> 13 | C15: =COUNTIFS(Enrollment_Data!$D$4:$D$2000,$A15,Enrollment_Data!$G$4:$G$2000,"Completed",Enrollment_Data!$F$4:$F$2000,IF($H$2="All","*",$H$2)) -> 2 | D15: =COUNTIFS(Enrollment_Data!$D$4:$D$2000,$A15,Enrollment_Data!$G$4:$G$2000,"Ongoing",Enrollment_Data!$F$4:$F$2000,IF($H$2="All","*",$H$2)) -> 10 | E15: =COUNTIFS(Enrollment_Data!$D$4:$D$2000,$A15,Enrollment_Data!$G$4:$G$2000,"Discontinued",Enrollment_Data!$F$4:$F$2000,IF($H$2="All","*",$H$2)) -> 1 | F15: =IFERROR(C15/B15,0) -> 0.15384615 | G15: =IFERROR(AVERAGEIFS(Enrollment_Data!$I$4:$I$2000,Enrollment_Data!$D$4:$D$2000,$A15,Enrollment_Data!$F$4:$F$2000,IF($H$2="All","*",$H$2)),0) -> 79.23 | H15: =IF(AND(B15>=MEDIAN($B$12:$B$18),F15<0.4),"High enrollment / low completion",IF(G15<50,"Performance review","Monitor")) -> High enrollment / low completion
A16: C# .NET Development | B16: =COUNTIFS(Enrollment_Data!$D$4:$D$2000,$A16,Enrollment_Data!$F$4:$F$2000,IF($H$2="All","*",$H$2)) -> 12 | C16: =COUNTIFS(Enrollment_Data!$D$4:$D$2000,$A16,Enrollment_Data!$G$4:$G$2000,"Completed",Enrollment_Data!$F$4:$F$2000,IF($H$2="All","*",$H$2)) -> 1 | D16: =COUNTIFS(Enrollment_Data!$D$4:$D$2000,$A16,Enrollment_Data!$G$4:$G$2000,"Ongoing",Enrollment_Data!$F$4:$F$2000,IF($H$2="All","*",$H$2)) -> 10 | E16: =COUNTIFS(Enrollment_Data!$D$4:$D$2000,$A16,Enrollment_Data!$G$4:$G$2000,"Discontinued",Enrollment_Data!$F$4:$F$2000,IF($H$2="All","*",$H$2)) -> 1 | F16: =IFERROR(C16/B16,0) -> 0.083333333 | G16: =IFERROR(AVERAGEIFS(Enrollment_Data!$I$4:$I$2000,Enrollment_Data!$D$4:$D$2000,$A16,Enrollment_Data!$F$4:$F$2000,IF($H$2="All","*",$H$2)),0) -> 70.7 | H16: =IF(AND(B16>=MEDIAN($B$12:$B$18),F16<0.4),"High enrollment / low completion",IF(G16<50,"Performance review","Monitor")) -> Monitor
A17: Data Structures & Algorithms | B17: =COUNTIFS(Enrollment_Data!$D$4:$D$2000,$A17,Enrollment_Data!$F$4:$F$2000,IF($H$2="All","*",$H$2)) -> 17 | C17: =COUNTIFS(Enrollment_Data!$D$4:$D$2000,$A17,Enrollment_Data!$G$4:$G$2000,"Completed",Enrollment_Data!$F$4:$F$2000,IF($H$2="All","*",$H$2)) -> 1 | D17: =COUNTIFS(Enrollment_Data!$D$4:$D$2000,$A17,Enrollment_Data!$G$4:$G$2000,"Ongoing",Enrollment_Data!$F$4:$F$2000,IF($H$2="All","*",$H$2)) -> 14 | E17: =COUNTIFS(Enrollment_Data!$D$4:$D$2000,$A17,Enrollment_Data!$G$4:$G$2000,"Discontinued",Enrollment_Data!$F$4:$F$2000,IF($H$2="All","*",$H$2)) -> 2 | F17: =IFERROR(C17/B17,0) -> 0.058823529 | G17: =IFERROR(AVERAGEIFS(Enrollment_Data!$I$4:$I$2000,Enrollment_Data!$D$4:$D$2000,$A17,Enrollment_Data!$F$4:$F$2000,IF($H$2="All","*",$H$2)),0) -> 62.483333 | H17: =IF(AND(B17>=MEDIAN($B$12:$B$18),F17<0.4),"High enrollment / low completion",IF(G17<50,"Performance review","Monitor")) -> High enrollment / low completion
A18: React Web Development | B18: =COUNTIFS(Enrollment_Data!$D$4:$D$2000,$A18,Enrollment_Data!$F$4:$F$2000,IF($H$2="All","*",$H$2)) -> 12 | C18: =COUNTIFS(Enrollment_Data!$D$4:$D$2000,$A18,Enrollment_Data!$G$4:$G$2000,"Completed",Enrollment_Data!$F$4:$F$2000,IF($H$2="All","*",$H$2)) -> 1 | D18: =COUNTIFS(Enrollment_Data!$D$4:$D$2000,$A18,Enrollment_Data!$G$4:$G$2000,"Ongoing",Enrollment_Data!$F$4:$F$2000,IF($H$2="All","*",$H$2)) -> 9 | E18: =COUNTIFS(Enrollment_Data!$D$4:$D$2000,$A18,Enrollment_Data!$G$4:$G$2000,"Discontinued",Enrollment_Data!$F$4:$F$2000,IF($H$2="All","*",$H$2)) -> 2 | F18: =IFERROR(C18/B18,0) -> 0.083333333 | G18: =IFERROR(AVERAGEIFS(Enrollment_Data!$I$4:$I$2000,Enrollment_Data!$D$4:$D$2000,$A18,Enrollment_Data!$F$4:$F$2000,IF($H$2="All","*",$H$2)),0) -> 74.02 | H18: =IF(AND(B18>=MEDIAN($B$12:$B$18),F18<0.4),"High enrollment / low completion",IF(G18<50,"Performance review","Monitor")) -> Monitor
A21: Performance Band | B21: Enrollments
A22: Below 40% | B22: =COUNTIFS(Enrollment_Data!$I$4:$I$2000,">=0",Enrollment_Data!$I$4:$I$2000,"<=39.999",Enrollment_Data!$C$4:$C$2000,IF($E$2="All","<>",INDEX(Course_Master!$A$4:$A$10,MATCH($E$2,Course_Master!$B$4:$B$10,0))),Enrollment_Data!$F$4:$F$2000,IF($H$2="All","*",$H$2)) -> 2
A23: 40–59% | B23: =COUNTIFS(Enrollment_Data!$I$4:$I$2000,">=40",Enrollment_Data!$I$4:$I$2000,"<=59.999",Enrollment_Data!$C$4:$C$2000,IF($E$2="All","<>",INDEX(Course_Master!$A$4:$A$10,MATCH($E$2,Course_Master!$B$4:$B$10,0))),Enrollment_Data!$F$4:$F$2000,IF($H$2="All","*",$H$2)) -> 17
A24: 60–79% | B24: =COUNTIFS(Enrollment_Data!$I$4:$I$2000,">=60",Enrollment_Data!$I$4:$I$2000,"<=79.999",Enrollment_Data!$C$4:$C$2000,IF($E$2="All","<>",INDEX(Course_Master!$A$4:$A$10,MATCH($E$2,Course_Master!$B$4:$B$10,0))),Enrollment_Data!$F$4:$F$2000,IF($H$2="All","*",$H$2)) -> 35
A25: 80–100% | B25: =COUNTIFS(Enrollment_Data!$I$4:$I$2000,">=80",Enrollment_Data!$I$4:$I$2000,"<=100",Enrollment_Data!$C$4:$C$2000,IF($E$2="All","<>",INDEX(Course_Master!$A$4:$A$10,MATCH($E$2,Course_Master!$B$4:$B$10,0))),Enrollment_Data!$F$4:$F$2000,IF($H$2="All","*",$H$2)) -> 19

Sheet Student_Data
A1: Student Data — SIMULATED SAMPLE RECORDS
A3: Student_ID | B3: Registration_Date | C3: Account_Status | D3: Last_Learning_Activity | E3: Activity_Status | F3: Month | G3: Data_Basis
A4: SAMP-001 | B4: 46177 | C4: Active | D4: 46201 | E4: Active | F4: 2026-06 | G4: Simulated for dashboard demonstration
A5: SAMP-002 | B5: 46177 | C5: Active | E5: No Recent Activity | F5: 2026-06 | G5: Simulated for dashboard demonstration
A6: SAMP-003 | B6: 46041 | C6: Active | D6: 46068 | E6: No Recent Activity | F6: 2026-01 | G6: Simulated for dashboard demonstration
A7: SAMP-004 | B7: 46070 | C7: Active | D7: 46139 | E7: No Recent Activity | F7: 2026-02 | G7: Simulated for dashboard demonstration
A8: SAMP-005 | B8: 46120 | C8: Active | D8: 46120 | E8: No Recent Activity | F8: 2026-04 | G8: Simulated for dashboard demonstration
A9: SAMP-006 | B9: 46076 | C9: Active | D9: 46103 | E9: No Recent Activity | F9: 2026-02 | G9: Simulated for dashboard demonstration
A10: SAMP-007 | B10: 46085 | C10: Active | D10: 46129 | E10: No Recent Activity | F10: 2026-03 | G10: Simulated for dashboard demonstration
A11: SAMP-008 | B11: 46151 | C11: Active | D11: 46202 | E11: Active | F11: 2026-05 | G11: Simulated for dashboard demonstration
A12: SAMP-009 | B12: 46115 | C12: Active | E12: No Recent Activity | F12: 2026-04 | G12: Simulated for dashboard demonstration
A13: SAMP-010 | B13: 46154 | C13: Active | D13: 46159 | E13: No Recent Activity | F13: 2026-05 | G13: Simulated for dashboard demonstration
A14: SAMP-011 | B14: 46181 | C14: Active | E14: No Recent Activity | F14: 2026-06 | G14: Simulated for dashboard demonstration
A15: SAMP-012 | B15: 46057 | C15: Active | D15: 46103 | E15: No Recent Activity | F15: 2026-02 | G15: Simulated for dashboard demonstration
A16: SAMP-013 | B16: 46065 | C16: Active | D16: 46074 | E16: No Recent Activity | F16: 2026-02 | G16: Simulated for dashboard demonstration
A17: SAMP-014 | B17: 46163 | C17: Active | D17: 46183 | E17: Active | F17: 2026-05 | G17: Simulated for dashboard demonstration
A18: SAMP-015 | B18: 46125 | C18: Active | E18: No Recent Activity | F18: 2026-04 | G18: Simulated for dashboard demonstration
A19: SAMP-016 | B19: 46191 | C19: Active | D19: 46198 | E19: Active | F19: 2026-06 | G19: Simulated for dashboard demonstration
A20: SAMP-017 | B20: 46055 | C20: Active | D20: 46063 | E20: No Recent Activity | F20: 2026-02 | G20: Simulated for dashboard demonstration
A21: SAMP-018 | B21: 46072 | C21: Inactive | D21: 46135 | E21: No Recent Activity | F21: 2026-02 | G21: Simulated for dashboard demonstration
A22: SAMP-019 | B22: 46133 | C22: Active | D22: 46164 | E22: No Recent Activity | F22: 2026-04 | G22: Simulated for dashboard demonstration
A23: SAMP-020 | B23: 46191 | C23: Active | D23: 46194 | E23: Active | F23: 2026-06 | G23: Simulated for dashboard demonstration
A24: SAMP-021 | B24: 46124 | C24: Active | E24: No Recent Activity | F24: 2026-04 | G24: Simulated for dashboard demonstration
A25: SAMP-022 | B25: 46158 | C25: Active | D25: 46172 | E25: No Recent Activity | F25: 2026-05 | G25: Simulated for dashboard demonstration
A26: SAMP-023 | B26: 46074 | C26: Active | D26: 46082 | E26: No Recent Activity | F26: 2026-02 | G26: Simulated for dashboard demonstration
A27: SAMP-024 | B27: 46125 | C27: Active | D27: 46157 | E27: No Recent Activity | F27: 2026-04 | G27: Simulated for dashboard demonstration
A28: SAMP-025 | B28: 46143 | C28: Active | D28: 46199 | E28: Active | F28: 2026-05 | G28: Simulated for dashboard demonstration
A29: SAMP-026 | B29: 46184 | C29: Active | D29: 46203 | E29: Active | F29: 2026-06 | G29: Simulated for dashboard demonstration
A30: SAMP-027 | B30: 46197 | C30: Active | D30: 46195 | E30: Active | F30: 2026-06 | G30: Simulated for dashboard demonstration
A31: SAMP-028 | B31: 46043 | C31: Active | D31: 46068 | E31: No Recent Activity | F31: 2026-01 | G31: Simulated for dashboard demonstration
A32: SAMP-029 | B32: 46065 | C32: Active | D32: 46132 | E32: No Recent Activity | F32: 2026-02 | G32: Simulated for dashboard demonstration
A33: SAMP-030 | B33: 46042 | C33: Active | D33: 46088 | E33: No Recent Activity | F33: 2026-01 | G33: Simulated for dashboard demonstration
A34: SAMP-031 | B34: 46089 | C34: Active | E34: No Recent Activity | F34: 2026-03 | G34: Simulated for dashboard demonstration
A35: SAMP-032 | B35: 46025 | C35: Active | D35: 46093 | E35: No Recent Activity | F35: 2026-01 | G35: Simulated for dashboard demonstration
A36: SAMP-033 | B36: 46058 | C36: Active | E36: No Recent Activity | F36: 2026-02 | G36: Simulated for dashboard demonstration
A37: SAMP-034 | B37: 46062 | C37: Active | D37: 46089 | E37: No Recent Activity | F37: 2026-02 | G37: Simulated for dashboard demonstration
A38: SAMP-035 | B38: 46167 | C38: Active | D38: 46197 | E38: Active | F38: 2026-05 | G38: Simulated for dashboard demonstration
A39: SAMP-036 | B39: 46194 | C39: Active | E39: No Recent Activity | F39: 2026-06 | G39: Simulated for dashboard demonstration
A40: SAMP-037 | B40: 46116 | C40: Active | D40: 46118 | E40: No Recent Activity | F40: 2026-04 | G40: Simulated for dashboard demonstration
A41: SAMP-038 | B41: 46160 | C41: Active | D41: 46169 | E41: No Recent Activity | F41: 2026-05 | G41: Simulated for dashboard demonstration
...

Sheet Enrollment_Data
A1: Enrollment Data — SIMULATED SAMPLE RECORDS
A3: Enrollment_ID | B3: Student_ID | C3: Course_ID | D3: Course_Name | E3: Enrollment_Date | F3: Enrollment_Month | G3: Enrollment_Status | H3: Completion_Date | I3: Assessment_Score_% | J3: Participation_Count | K3: Last_Activity_Date | L3: Data_Basis
A4: ENR-0001 | B4: SAMP-001 | C4: 3 | D4: Flutter Mobile Development | E4: 46198 | F4: 2026-06 | G4: Ongoing | I4: 55.4 | J4: 11 | K4: 46198 | L4: Simulated for dashboard demonstration
A5: ENR-0002 | B5: SAMP-001 | C5: 2 | D5: Python Programming Mastery | E5: 46177 | F5: 2026-06 | G5: Ongoing | J5: 0 | K5: 46179 | L5: Simulated for dashboard demonstration
A6: ENR-0003 | B6: SAMP-002 | C6: 5 | D6: C# .NET Development | E6: 46181 | F6: 2026-06 | G6: Ongoing | J6: 12 | K6: 46190 | L6: Simulated for dashboard demonstration
A7: ENR-0004 | B7: SAMP-002 | C7: 3 | D7: Flutter Mobile Development | E7: 46182 | F7: 2026-06 | G7: Ongoing | I7: 84.7 | J7: 17 | K7: 46182 | L7: Simulated for dashboard demonstration
A8: ENR-0005 | B8: SAMP-003 | C8: 5 | D8: C# .NET Development | E8: 46067 | F8: 2026-02 | G8: Ongoing | I8: 77 | J8: 9 | K8: 46139 | L8: Simulated for dashboard demonstration
A9: ENR-0006 | B9: SAMP-003 | C9: 3 | D9: Flutter Mobile Development | E9: 46195 | F9: 2026-06 | G9: Ongoing | I9: 76.4 | J9: 9 | K9: 46203 | L9: Simulated for dashboard demonstration
A10: ENR-0007 | B10: SAMP-004 | C10: 7 | D10: React Web Development | E10: 46093 | F10: 2026-03 | G10: Ongoing | J10: 11 | K10: 46191 | L10: Simulated for dashboard demonstration
A11: ENR-0008 | B11: SAMP-004 | C11: 1 | D11: Complete Java Programming | E11: 46103 | F11: 2026-03 | G11: Ongoing | I11: 71 | J11: 1 | K11: 46117 | L11: Simulated for dashboard demonstration
A12: ENR-0009 | B12: SAMP-005 | C12: 6 | D12: Data Structures & Algorithms | E12: 46139 | F12: 2026-04 | G12: Ongoing | J12: 5 | K12: 46194 | L12: Simulated for dashboard demonstration
A13: ENR-0010 | B13: SAMP-006 | C13: 3 | D13: Flutter Mobile Development | E13: 46169 | F13: 2026-05 | G13: Ongoing | J13: 12 | K13: 46182 | L13: Simulated for dashboard demonstration
A14: ENR-0011 | B14: SAMP-007 | C14: 6 | D14: Data Structures & Algorithms | E14: 46130 | F14: 2026-04 | G14: Ongoing | J14: 5 | K14: 46160 | L14: Simulated for dashboard demonstration
A15: ENR-0012 | B15: SAMP-007 | C15: 1 | D15: Complete Java Programming | E15: 46195 | F15: 2026-06 | G15: Ongoing | J15: 11 | K15: 46201 | L15: Simulated for dashboard demonstration
A16: ENR-0013 | B16: SAMP-008 | C16: 7 | D16: React Web Development | E16: 46202 | F16: 2026-06 | G16: Ongoing | J16: 2 | K16: 46203 | L16: Simulated for dashboard demonstration
A17: ENR-0014 | B17: SAMP-008 | C17: 6 | D17: Data Structures & Algorithms | E17: 46165 | F17: 2026-05 | G17: Ongoing | I17: 54.3 | J17: 8 | K17: 46179 | L17: Simulated for dashboard demonstration
A18: ENR-0015 | B18: SAMP-009 | C18: 2 | D18: Python Programming Mastery | E18: 46166 | F18: 2026-05 | G18: Discontinued | J18: 0 | K18: 46183 | L18: Simulated for dashboard demonstration
A19: ENR-0016 | B19: SAMP-010 | C19: 5 | D19: C# .NET Development | E19: 46179 | F19: 2026-06 | G19: Ongoing | J19: 1 | K19: 46182 | L19: Simulated for dashboard demonstration
A20: ENR-0017 | B20: SAMP-011 | C20: 3 | D20: Flutter Mobile Development | E20: 46189 | F20: 2026-06 | G20: Ongoing | I20: 70.4 | J20: 17 | K20: 46190 | L20: Simulated for dashboard demonstration
A21: ENR-0018 | B21: SAMP-011 | C21: 2 | D21: Python Programming Mastery | E21: 46193 | F21: 2026-06 | G21: Ongoing | I21: 60 | J21: 14 | K21: 46193 | L21: Simulated for dashboard demonstration
A22: ENR-0019 | B22: SAMP-011 | C22: 5 | D22: C# .NET Development | E22: 46197 | F22: 2026-06 | G22: Ongoing | I22: 67.6 | J22: 12 | K22: 46200 | L22: Simulated for dashboard demonstration
A23: ENR-0020 | B23: SAMP-012 | C23: 6 | D23: Data Structures & Algorithms | E23: 46141 | F23: 2026-04 | G23: Ongoing | I23: 49.4 | J23: 10 | K23: 46173 | L23: Simulated for dashboard demonstration
A24: ENR-0021 | B24: SAMP-013 | C24: 4 | D24: C/C++ Programming Course | E24: 46148 | F24: 2026-05 | G24: Ongoing | I24: 82.2 | J24: 0 | K24: 46191 | L24: Simulated for dashboard demonstration
A25: ENR-0022 | B25: SAMP-014 | C25: 2 | D25: Python Programming Mastery | E25: 46199 | F25: 2026-06 | G25: Discontinued | I25: 82.5 | J25: 10 | K25: 46200 | L25: Simulated for dashboard demonstration
A26: ENR-0023 | B26: SAMP-014 | C26: 5 | D26: C# .NET Development | E26: 46190 | F26: 2026-06 | G26: Ongoing | I26: 65.4 | J26: 17 | K26: 46197 | L26: Simulated for dashboard demonstration
A27: ENR-0024 | B27: SAMP-015 | C27: 7 | D27: React Web Development | E27: 46146 | F27: 2026-05 | G27: Ongoing | I27: 85.6 | J27: 11 | K27: 46151 | L27: Simulated for dashboard demonstration
A28: ENR-0025 | B28: SAMP-015 | C28: 6 | D28: Data Structures & Algorithms | E28: 46155 | F28: 2026-05 | G28: Ongoing | I28: 73 | J28: 16 | K28: 46194 | L28: Simulated for dashboard demonstration
A29: ENR-0026 | B29: SAMP-016 | C29: 1 | D29: Complete Java Programming | E29: 46197 | F29: 2026-06 | G29: Ongoing | I29: 75 | J29: 13 | K29: 46200 | L29: Simulated for dashboard demonstration
A30: ENR-0027 | B30: SAMP-016 | C30: 4 | D30: C/C++ Programming Course | E30: 46197 | F30: 2026-06 | G30: Ongoing | I30: 93.7 | J30: 0 | K30: 46203 | L30: Simulated for dashboard demonstration
A31: ENR-0028 | B31: SAMP-017 | C31: 2 | D31: Python Programming Mastery | E31: 46187 | F31: 2026-06 | G31: Ongoing | I31: 54.7 | J31: 0 | K31: 46190 | L31: Simulated for dashboard demonstration
A32: ENR-0029 | B32: SAMP-018 | C32: 7 | D32: React Web Development | E32: 46153 | F32: 2026-05 | G32: Ongoing | J32: 17 | K32: 46180 | L32: Simulated for dashboard demonstration
A33: ENR-0030 | B33: SAMP-018 | C33: 4 | D33: C/C++ Programming Course | E33: 46186 | F33: 2026-06 | G33: Ongoing | J33: 9 | K33: 46193 | L33: Simulated for dashboard demonstration
A34: ENR-0031 | B34: SAMP-019 | C34: 3 | D34: Flutter Mobile Development | E34: 46195 | F34: 2026-06 | G34: Ongoing | I34: 82.2 | J34: 11 | K34: 46203 | L34: Simulated for dashboard demonstration
A35: ENR-0032 | B35: SAMP-019 | C35: 5 | D35: C# .NET Development | E35: 46143 | F35: 2026-05 | G35: Completed | H35: 46172 | I35: 77.4 | J35: 7 | K35: 46147 | L35: Simulated for dashboard demonstration
A36: ENR-0033 | B36: SAMP-020 | C36: 3 | D36: Flutter Mobile Development | E36: 46199 | F36: 2026-06 | G36: Ongoing | I36: 78.9 | J36: 1 | K36: 46203 | L36: Simulated for dashboard demonstration
A37: ENR-0034 | B37: SAMP-021 | C37: 1 | D37: Complete Java Programming | E37: 46169 | F37: 2026-05 | G37: Discontinued | I37: 59.9 | J37: 0 | K37: 46195 | L37: Simulated for dashboard demonstration
A38: ENR-0035 | B38: SAMP-022 | C38: 6 | D38: Data Structures & Algorithms | E38: 46196 | F38: 2026-06 | G38: Ongoing | I38: 69.7 | J38: 13 | K38: 46198 | L38: Simulated for dashboard demonstration
A39: ENR-0036 | B39: SAMP-022 | C39: 5 | D39: C# .NET Development | E39: 46187 | F39: 2026-06 | G39: Ongoing | J39: 13 | K39: 46187 | L39: Simulated for dashboard demonstration
A40: ENR-0037 | B40: SAMP-023 | C40: 4 | D40: C/C++ Programming Course | E40: 46108 | F40: 2026-03 | G40: Ongoing | I40: 88 | J40: 11 | K40: 46135 | L40: Simulated for dashboard demonstration
A41: ENR-0038 | B41: SAMP-024 | C41: 3 | D41: Flutter Mobile Development | E41: 46160 | F41: 2026-05 | G41: Ongoing | J41: 3 | K41: 46190 | L41: Simulated for dashboard demonstration
...

Sheet Course_Master
A1: CDaX Course Master — catalog values from supplied source file
A3: Course_ID | B3: Course_Name | C3: Category | D3: Instructor | E3: Level | F3: Data_Basis
A4: 1 | B4: Complete Java Programming | C4: Programming | D4: Dr. Rajesh Verma | E4: Intermediate | F4: Actual catalog field from CDaX PowerBI Data 11.xlsx
A5: 2 | B5: Python Programming Mastery | C5: Programming | D5: Prof. Anjali Desai | E5: Beginner | F5: Actual catalog field from CDaX PowerBI Data 11.xlsx
A6: 3 | B6: Flutter Mobile Development | C6: Mobile Development | D6: Dr. Rajesh Verma | E6: Beginner | F6: Actual catalog field from CDaX PowerBI Data 11.xlsx
A7: 4 | B7: C/C++ Programming Course | C7: Programming | D7: Prof. Anjali Desai | E7: Intermediate | F7: Actual catalog field from CDaX PowerBI Data 11.xlsx
A8: 5 | B8: C# .NET Development | C8: Programming | D8: Dr. Rajesh Verma | E8: Intermediate | F8: Actual catalog field from CDaX PowerBI Data 11.xlsx
A9: 6 | B9: Data Structures & Algorithms | C9: Computer Science | D9: Prof. Anjali Desai | E9: Advanced | F9: Actual catalog field from CDaX PowerBI Data 11.xlsx
A10: 7 | B10: React Web Development | C10: Web Development | D10: Dr. Rajesh Verma | E10: Intermediate | F10: Actual catalog field from CDaX PowerBI Data 11.xlsx

Sheet Monthly_Trends
A1: Monthly Enrollment and Registration Trends — simulated sample data
A3: Month | B3: New Registrations | C3: Course Enrollments | D3: Completed Enrollments | E3: Average Assessment Score | F3: Data_Basis
A4: 2026-01 | B4: =COUNTIF(Student_Data!$F$4:$F$1000,A4) -> 11 | C4: =COUNTIF(Enrollment_Data!$F$4:$F$2000,A4) -> 3 | D4: =COUNTIFS(Enrollment_Data!$F$4:$F$2000,A4,Enrollment_Data!$G$4:$G$2000,"Completed") -> 0 | E4: =IFERROR(AVERAGEIF(Enrollment_Data!$F$4:$F$2000,A4,Enrollment_Data!$I$4:$I$2000),0) -> 78.733333 | F4: Simulated for dashboard demonstration
A5: 2026-02 | B5: =COUNTIF(Student_Data!$F$4:$F$1000,A5) -> 14 | C5: =COUNTIF(Enrollment_Data!$F$4:$F$2000,A5) -> 7 | D5: =COUNTIFS(Enrollment_Data!$F$4:$F$2000,A5,Enrollment_Data!$G$4:$G$2000,"Completed") -> 1 | E5: =IFERROR(AVERAGEIF(Enrollment_Data!$F$4:$F$2000,A5,Enrollment_Data!$I$4:$I$2000),0) -> 61.72 | F5: Simulated for dashboard demonstration
A6: 2026-03 | B6: =COUNTIF(Student_Data!$F$4:$F$1000,A6) -> 4 | C6: =COUNTIF(Enrollment_Data!$F$4:$F$2000,A6) -> 7 | D6: =COUNTIFS(Enrollment_Data!$F$4:$F$2000,A6,Enrollment_Data!$G$4:$G$2000,"Completed") -> 2 | E6: =IFERROR(AVERAGEIF(Enrollment_Data!$F$4:$F$2000,A6,Enrollment_Data!$I$4:$I$2000),0) -> 79.783333 | F6: Simulated for dashboard demonstration
A7: 2026-04 | B7: =COUNTIF(Student_Data!$F$4:$F$1000,A7) -> 10 | C7: =COUNTIF(Enrollment_Data!$F$4:$F$2000,A7) -> 15 | D7: =COUNTIFS(Enrollment_Data!$F$4:$F$2000,A7,Enrollment_Data!$G$4:$G$2000,"Completed") -> 3 | E7: =IFERROR(AVERAGEIF(Enrollment_Data!$F$4:$F$2000,A7,Enrollment_Data!$I$4:$I$2000),0) -> 74.681818 | F7: Simulated for dashboard demonstration
A8: 2026-05 | B8: =COUNTIF(Student_Data!$F$4:$F$1000,A8) -> 11 | C8: =COUNTIF(Enrollment_Data!$F$4:$F$2000,A8) -> 22 | D8: =COUNTIFS(Enrollment_Data!$F$4:$F$2000,A8,Enrollment_Data!$G$4:$G$2000,"Completed") -> 3 | E8: =IFERROR(AVERAGEIF(Enrollment_Data!$F$4:$F$2000,A8,Enrollment_Data!$I$4:$I$2000),0) -> 71.16875 | F8: Simulated for dashboard demonstration
A9: 2026-06 | B9: =COUNTIF(Student_Data!$F$4:$F$1000,A9) -> 10 | C9: =COUNTIF(Enrollment_Data!$F$4:$F$2000,A9) -> 50 | D9: =COUNTIFS(Enrollment_Data!$F$4:$F$2000,A9,Enrollment_Data!$G$4:$G$2000,"Completed") -> 0 | E9: =IFERROR(AVERAGEIF(Enrollment_Data!$F$4:$F$2000,A9,Enrollment_Data!$I$4:$I$2000),0) -> 67.7125 | F9: Simulated for dashboard demonstration

Sheet Recommendations
A1: Course Improvement Recommendations
A3: Signal | B3: Rule / Evidence | C3: Potential interpretation | D3: Recommended action | E3: Caution
A4: High enrollment + low completion | B4: Enrollment count at/above course median and completion rate below 40% | C4: Possible course friction or learner support gap; sample data cannot establish cause | D4: Review module-level drop-off, course structure, class support, and student feedback | E4: Threshold is an illustrative rule, not a validated CDaX standard
A5: Low assessment score | B5: Average assessment score below 50% | C5: May indicate difficult content, unclear instruction, or assessment mismatch | D5: Review question quality, learning objectives, explanations, and module prerequisites | E5: Do not infer cause from score alone
A6: High discontinued share | B6: Discontinued enrollments / course enrollments above 25% | C6: Potential engagement or completion barrier | D6: Review last activity, course length, onboarding, and support response times | E6: Discontinued status is simulated for demonstration
A7: No recent activity | B7: Last learning activity more than 30 days before sample cutoff, or missing activity | C7: Possible disengagement; validate actual event logs | D7: Test a re-engagement message and offer mentor support | E7: Activity cutoff and data are simulated
A8: Low enrollment | B8: Course enrollments below portfolio median | C8: Could reflect low visibility, demand, or small sample | D8: Compare discovery page views, favorites, conversion, and course positioning | E8: Catalog popularity counts are source fields, not same as this sample enrollment count
A9: Assessment data gap | B9: Actual assessment response records not included in supplied sample workbook | C9: Cannot calculate actual academic performance from current source alone | D9: Connect assessment attempts, marks, question-level results and pass status | E9: Sample score column is simulated and must be replaced before real reporting

Sheet Source_Notes
A1: Source Data, Assumptions & Usage Notes
A3: Area | B3: Source / Assumption | C3: How used | D3: Important limitation
A4: Course catalog | B4: Actual source: CDaX PowerBI Data 11.xlsx → Courses (7 course records) | C4: Course IDs, titles, categories, instructors and levels copied into Course_Master | D4: Source catalog includes published/course metadata and a catalog enrolled_students field; that field is not used as student-level enrollments in this dashboard
A5: User records | B5: Actual source contains 3 user rows in Users | C5: Reviewed as source context only; sample dashboard uses simulated student records to make filters/charts demonstrable | D5: Actual source is too small for robust trends
A6: Purchases | B6: Actual source contains 5 populated purchase rows with user/course/date fields | C6: Used as evidence that transaction data exists, but not directly treated as enrollment lifecycle status | D6: Purchase rows do not establish course completion or assessment score
A7: Learning activity | B7: Actual source has 4 populated Video_Progress rows in the reviewed workbook | C7: Shows limited activity events exist | D7: Not enough to infer portfolio-wide monthly activity; no universal activity definition in source
A8: Student_Data | B8: 60 simulated student records, registration dates Jan–Jun 2026 | C8: Demonstrates monthly registration and active/inactive filters | D8: All SAMP IDs and activity status are simulated; replace with actual student-level records
A9: Enrollment_Data | B9: Simulated enrollments linked to actual catalog course IDs and titles | C9: Demonstrates status, completion, score, and participation analysis | D9: Enrollment dates/statuses/scores are invented sample values, not actual CDaX outcomes
A10: Active definition | B10: Illustrative: account active/inactive and last learning activity within 30 days are separate measures | C10: Account status used in active/inactive KPI; recent activity KPI uses last activity | D10: Change threshold/definition to match CDaX event tracking rules
A11: Completion rate | B11: Completed enrollments divided by all enrollments in the selected filter | C11: Used for KPI and course comparison | D11: Status is simulated until actual completion events/status are available
A12: Assessment score | B12: Average of nonblank simulated enrollment assessment scores | C12: Used for demonstration of performance analysis | D12: Actual assessment attempts/scores are not in the supplied sample workbook; do not present simulated score as real academic performance
A13: Dashboard filters | B13: Dashboard cells E2 (Course) and H2 (Month) have dropdowns | C13: KPI cards and course table respond to month and course selection where relevant | D13: Course-wise table/chart summarizes each course for selected month; student registration KPI is filtered by registration month
A14: Refresh/update | B14: Replace or append rows in the data tables, preserving headers and formula ranges | C14: Dashboard formulas recalculate in Excel | D14: Formula ranges currently cover rows 4–2000; extend formulas/ranges if exceeding that size
A15: Suggested next integration | B15: Users, Purchases, Video_Progress, User_Streaks, assessment attempts/results, enrollment/completion events | C15: Map stable user_id, course_id and timestamps; define active, discontinued and completion status | D15: Keep sample data separate from production data and remove/clearly flag sample records before reporting
